Workbook

Sheet 테스트 케이스
A1: POTATO SURVIVORS — QA 테스트 케이스 (2회차: 회귀 + 탐색)
A2: 2회차 = 1회차 TC 55개(회귀) + 탐색 TC 10개 + 보스 라운드 TC 9개. Fail은 Jira(SCRUM-n)에 등록하고, 원인과 수정 커밋은 비고에, 수정 후 결과는 재검증 칸에 기록했습니다.
A3: TC ID | B3: 대분류 | C3: 테스트 항목 | D3: 사전조건 | E3: 테스트 절차 | F3: 기대 결과 | G3: 실제 결과 | H3: 결과 | I3: 비고 | J3: 1회차 이력 | K3: Jira 이슈 | L3: 재검증
A4: TC-001 | B4: 로비 | C4: 게임 최초 실행 | D4: 게임을 처음 실행 | E4: 에디터/빌드로 게임 실행 | F4: MainMenu 씬이 먼저 표시(타이틀 로고·무기 6종·시작/종료 버튼) | H4: Pass
A5: TC-002 | B5: 로비 | C5: 무기 선택 | D5: 로비 화면 | E5: 무기 카드 클릭 | F5: 선택 카드가 노란색 하이라이트 + 하단에 선택 무기 정보 표시 | H5: Pass
A6: TC-003 | B6: 로비 | C6: 게임 시작 | D6: 무기 1개 선택 | E6: '게임 시작' 클릭 | F6: 게임 씬 진입 + 선택 무기를 장착한 상태로 시작 | H6: Pass
A7: TC-004 | B7: 로비 | C7: 무기 미선택 시작 | D7: 로비 진입 직후(카드 클릭 안 함) | E7: '게임 시작' 클릭 | F7: 첫 무기가 기본 선택된 상태로 시작(빈손 시작 없음) | H7: Pass | J7: 보류 → 사양 확정(첫 무기 기본 선택)
A8: TC-005 | B8: 로비 | C8: 종료 | D8: 로비 화면 | E8: '종료' 클릭 | F8: 게임 종료(에디터는 플레이 모드 중지) | H8: Pass
A9: TC-006 | B9: 이동 | C9: 기본 이동 | D9: 게임 진행 중 | E9: WASD/방향키 입력 | F9: 플레이어가 해당 방향으로 이동 | H9: Pass
A10: TC-007 | B10: 이동 | C10: 화면 경계 | D10: 플레이어를 화면 끝으로 | E10: 화면 밖으로 계속 이동 시도 | F10: 카메라 화면 경계를 벗어나지 않음 | H10: Pass | J10: Fail → edgePadding 수정, 재검증 Pass
A11: TC-008 | B11: 전투 | C11: 근접 자동공격 | D11: 근접 무기 장착·적 존재 | E11: 적이 감지 범위에 진입 | F11: 무기가 자동 스핀 공격하여 적에게 피해 | H11: Pass
A12: TC-009 | B12: 전투 | C12: 원거리 발사 | D12: 원거리 무기 장착·적 존재 | E12: 적 감지 | F12: 투사체가 적 방향으로 발사되어 피해 | H12: Pass
A13: TC-010 | B13: 전투 | C13: 샷건 산탄 | D13: 샷건 장착 | E13: 공격 발동 | F13: 투사체 5발이 부채꼴로 발사 | H13: Pass
A14: TC-011 | B14: 전투 | C14: 쿨다운 | D14: 공격 직후 | E14: 쿨다운 시간 대기 | F14: 쿨다운 경과 후 다음 공격 발동 | H14: Pass
A15: TC-012 | B15: 전투 | C15: 적 없음 | D15: 주변에 적 없음 | E15: 대기 | F15: 무기가 공격하지 않음(투사체 낭비 없음) | H15: Pass
A16: TC-013 | B16: 전투 | C16: 관통 | D16: 관통 무기(석궁 등) | E16: 투사체가 적 명중 | F16: 지정 관통 수만큼 적을 통과하며 타격 | H16: Pass
A17: TC-014 | B17: 몬스터 | C17: 스폰 위치 | D17: 웨이브 시작 | E17: 웨이브 개시 | F17: 몬스터가 화면 안 영역에 스폰 | H17: Pass
A18: TC-015 | B18: 몬스터 | C18: 추격 | D18: 몬스터 스폰됨 | E18: 시간 경과 | F18: 몬스터가 플레이어를 추격 | H18: Pass
A19: TC-016 | B19: 몬스터 | C19: 근접 공격 | D19: 몬스터가 플레이어에 접촉 | E19: 접촉 유지 | F19: 플레이어 HP 감소 | H19: Pass
A20: TC-017 | B20: 몬스터 | C20: 원거리 몬스터 | D20: 원거리 몬스터 존재 | E20: 사거리 내 플레이어 | F20: 몬스터가 플레이어에게 투사체 발사(플레이어만 피격, 몬스터끼리 X) | H20: Pass
A21: TC-018 | B21: 보스 | C21: 등장 주기 | D21: 스테이지 진행 | E21: 5스테이지 도달 | F21: 보스가 등장(2라운드에는 안 나옴) | H21: Pass | J21: Fail → SpawnConfig 자동 주입, 재검증 Pass
A22: TC-019 | B22: 몬스터 | C22: 처치 보상 | D22: 몬스터에 피해 누적 | E22: 몬스터 처치 | F22: 코인이 드랍됨 | H22: Pass
A23: TC-020 | B23: 웨이브 | C23: 시간 종료 | D23: 웨이브 진행 중 | E23: 20초 경과 | F23: 웨이브 종료 후 상점 오픈 | H23: Pass
A24: TC-021 | B24: 웨이브 | C24: 전멸 무관 | D24: 웨이브 진행 중 | E24: 시간 남은 채 모든 몬스터 처치 | F24: 웨이브가 끝나지 않고 계속 진행(시간 기반) | H24: Pass
A25: TC-022 | B25: 스테이지 | C25: 번호 증가 | D25: 상점 화면 | E25: '다음 라운드' 클릭 | F25: 스테이지 번호 +1 후 웨이브 재개 | H25: Pass
A26: TC-023 | B26: HP | C26: 체력바 감소 | D26: 플레이어 피격 | E26: 피해 받음 | F26: 머리 위 체력바가 감소 | H26: Pass
A27: TC-024 | B27: 사망 | C27: 게임오버 | D27: 플레이어 HP 0 | E27: HP가 0이 됨 | F27: 게임오버 패널 표시 + 게임 일시정지 | H27: Pass
A28: TC-025 | B28: 게임오버 | C28: 재시작 | D28: 게임오버 패널 | E28: '다시 시작' 클릭 | F28: 현재 씬 리로드(초기화) + 시작 무기 재지급 | H28: Pass
A29: TC-026 | B29: 게임오버 | C29: 로비 복귀 | D29: 게임오버 패널 | E29: '로비로' 클릭 | F29: MainMenu 복귀 + 시작 무기 선택 초기화 | H29: Pass
A30: TC-027 | B30: 코인 | C30: 드랍 | D30: 몬스터 처치 | E30: 처치 발생 | F30: 코인이 바닥에 드랍 | H30: Pass
A31: TC-028 | B31: 코인 | C31: 자석 획득 | D31: 코인 드랍됨 | E31: 플레이어가 코인에 접근 | F31: 코인이 흡수되어 골드 증가 | H31: Pass | J31: Fail → 자석 범위 상향, 재검증 Pass
A32: TC-029 | B32: 코인 | C32: HUD 갱신 | D32: 코인 획득 | E32: 골드 증가 | F32: HUD 골드 수치가 즉시 갱신 | H32: Pass
A33: TC-030 | B33: 상점 | C33: 자동 오픈 | D33: 웨이브 종료 | E33: 종료 시점 | F33: 상점 자동으로 열리고 게임 일시정지 | G33: 상점에서 F1 배속 버튼을 누르면 일시정지가 풀려 투사체가 계속 이동함 | H33: Fail | I33: 원인: 디버그 배속이 timeScale=0을 덮어씀 / 수정 a93085f | K33: SCRUM-5 | L33: Pass
A34: TC-031 | B34: 상점 | C34: 신규 표시 | D34: 안 가진 무기가 카드에 뜸 | E34: 카드 확인 | F34: '무기명 Lv1 (신규)'로 표시 | H34: Pass
A35: TC-032 | B35: 상점 | C35: 강화 표시 | D35: 보유 무기가 카드에 뜸 | E35: 카드 확인 | F35: '무기명 Lv(현재+1) (강화)'로 표시 | H35: Pass
A36: TC-033 | B36: 상점 | C36: 만렙 제외 | D36: 특정 무기 Lv5 보유 | E36: 상점 여러 번 확인 | F36: 해당 무기가 카드에 뜨지 않음 | H36: Pass
A37: TC-034 | B37: 상점 | C37: 무기 구매 | D37: 골드 충분·무기 카드 | E37: 카드 구매 | F37: 무기 장착 또는 레벨업 + 골드 차감 | H37: Pass
A38: TC-035 | B38: 상점 | C38: 골드 부족 | D38: 골드 < 가격 | E38: 카드 확인 | F38: 구매 버튼 비활성(구매 불가) | H38: Pass
A39: TC-036 | B39: 상점 | C39: 슬롯 만석 | D39: 6슬롯 가득 + 신규 무기 | E39: 구매 시도 | F39: 구매 실패 + 골드 환불 | H39: Pass
A40: TC-037 | B40: 상점 | C40: 만렙 환불 | D40: 만렙 무기 카드가 남은 경우 | E40: 구매 시도 | F40: 구매 실패 + 골드 환불 | H40: Pass | J40: Block(만렙 상태를 수동으로 재현할 수 없어 테스트 불가) → 디버그 콘솔로 재현 수단을 만든 뒤 실행, Pass
...

Sheet 요약
A1: 테스트 요약 | D1: 대분류별 케이스 수
D2: 대분류 | E2: 개수
A3: 전체 케이스 | B3: =COUNTA('테스트 케이스'!A4:A77) | D3: 로비 | E3: =COUNTIF('테스트 케이스'!B4:B77,D3)
A4: Pass | B4: =COUNTIF('테스트 케이스'!H4:H77,"Pass") | D4: 이동 | E4: =COUNTIF('테스트 케이스'!B4:B77,D4)
A5: Fail | B5: =COUNTIF('테스트 케이스'!H4:H77,"Fail") | D5: 전투 | E5: =COUNTIF('테스트 케이스'!B4:B77,D5)
A6: N/A | B6: =COUNTIF('테스트 케이스'!H4:H77,"N/A") | D6: 몬스터 | E6: =COUNTIF('테스트 케이스'!B4:B77,D6)
A7: 보류 | B7: =COUNTIF('테스트 케이스'!H4:H77,"보류") | D7: 보스 | E7: =COUNTIF('테스트 케이스'!B4:B77,D7)
A8: 미실행 | B8: =COUNTA('테스트 케이스'!A4:A77)-COUNTA('테스트 케이스'!H4:H77) | D8: 웨이브 | E8: =COUNTIF('테스트 케이스'!B4:B77,D8)
D9: 스테이지 | E9: =COUNTIF('테스트 케이스'!B4:B77,D9)
D10: HP | E10: =COUNTIF('테스트 케이스'!B4:B77,D10)
A11: 성공률 Pass÷(전체−N/A) | B11: =IF(B3-B6=0,0,B4/(B3-B6)) | D11: 사망 | E11: =COUNTIF('테스트 케이스'!B4:B77,D11)
A12: 진행률 (전체−미실행)÷전체 | B12: =IF(B3=0,0,(B3-B8)/B3) | D12: 게임오버 | E12: =COUNTIF('테스트 케이스'!B4:B77,D12)
A13: Jira 연결 TC 수 | B13: =COUNTA('테스트 케이스'!K4:K77) | D13: 코인 | E13: =COUNTIF('테스트 케이스'!B4:B77,D13)
A14: 1회차 대비 | B14: 1회차: Pass 47 / Fail 5 / Block 1 / 보류 1 / 미실행 1 (전체 55) | D14: 상점 | E14: =COUNTIF('테스트 케이스'!B4:B77,D14)
A15: 발견 버그 재검증 Pass | B15: =COUNTIF('테스트 케이스'!L4:L77,"Pass") | D15: 세트 | E15: =COUNTIF('테스트 케이스'!B4:B77,D15)
A16: 발견 버그 재검증 Fail | B16: =COUNTIF('테스트 케이스'!L4:L77,"Fail") | D16: HUD | E16: =COUNTIF('테스트 케이스'!B4:B77,D16)
D17: 아이콘 | E17: =COUNTIF('테스트 케이스'!B4:B77,D17)
D18: 무기 | E18: =COUNTIF('테스트 케이스'!B4:B77,D18)
D19: 탐색 | E19: =COUNTIF('테스트 케이스'!B4:B77,D19)
