Workbook

Sheet 요약
A1: Test Report
A3: 마일스톤(빌드) | B3: 1.6.61 (10/15 정기점검)
A4: 테스트 기간 | B4: 2026-10-15 ~ 2026-10-22
A5: 담당자 | B5: 김성재
A6: 테스트 환경 | B6: iPhone 14 (iOS 18.7.8), MuMu 앱플레이어 (Android)
A8: 테스트 항목 | B8: Pass | C8: Fail | D8: Block | E8: N/A | F8: N/T | G8: Total | H8: 진행률 | I8: 성공률
A9: 오류 수정 | B9: =SUMPRODUCT(ISNUMBER(TC!$A$4:$A$123)*(TC!$C$4:$C$123=$A9)*(TC!$J$4:$J$123="Pass"))+SUMPRODUCT(ISNUMBER(TC!$A$4:$A$123)*(TC!$C$4:$C$123=$A9)*(TC!$J$4:$J$123="")*(TC!$I$4:$I$123="Pass")) | C9: =SUMPRODUCT(ISNUMBER(TC!$A$4:$A$123)*(TC!$C$4:$C$123=$A9)*(TC!$J$4:$J$123="Fail"))+SUMPRODUCT(ISNUMBER(TC!$A$4:$A$123)*(TC!$C$4:$C$123=$A9)*(TC!$J$4:$J$123="")*(TC!$I$4:$I$123="Fail")) | D9: =SUMPRODUCT(ISNUMBER(TC!$A$4:$A$123)*(TC!$C$4:$C$123=$A9)*(TC!$J$4:$J$123="Block"))+SUMPRODUCT(ISNUMBER(TC!$A$4:$A$123)*(TC!$C$4:$C$123=$A9)*(TC!$J$4:$J$123="")*(TC!$I$4:$I$123="Block")) | E9: =SUMPRODUCT(ISNUMBER(TC!$A$4:$A$123)*(TC!$C$4:$C$123=$A9)*(TC!$J$4:$J$123="N/A"))+SUMPRODUCT(ISNUMBER(TC!$A$4:$A$123)*(TC!$C$4:$C$123=$A9)*(TC!$J$4:$J$123="")*(TC!$I$4:$I$123="N/A")) | F9: =SUMPRODUCT(ISNUMBER(TC!$A$4:$A$123)*(TC!$C$4:$C$123=$A9)*(TC!$J$4:$J$123="N/T"))+SUMPRODUCT(ISNUMBER(TC!$A$4:$A$123)*(TC!$C$4:$C$123=$A9)*(TC!$J$4:$J$123="")*(TC!$I$4:$I$123="N/T"))+SUMPRODUCT(ISNUMBER(TC!$A$4:$A$123)*(TC!$C$4:$C$123=$A9)*(TC!$J$4:$J$123="")*(TC!$I$4:$I$123="")) | G9: =SUMPRODUCT(ISNUMBER(TC!$A$4:$A$123)*(TC!$C$4:$C$123=$A9)) | H9: =IF(G9=0,0,(G9-F9)/G9) | I9: =IF(G9-E9=0,0,B9/(G9-E9))
A10: 신규 콘텐츠 | B10: =SUMPRODUCT(ISNUMBER(TC!$A$4:$A$123)*(TC!$C$4:$C$123=$A10)*(TC!$J$4:$J$123="Pass"))+SUMPRODUCT(ISNUMBER(TC!$A$4:$A$123)*(TC!$C$4:$C$123=$A10)*(TC!$J$4:$J$123="")*(TC!$I$4:$I$123="Pass")) | C10: =SUMPRODUCT(ISNUMBER(TC!$A$4:$A$123)*(TC!$C$4:$C$123=$A10)*(TC!$J$4:$J$123="Fail"))+SUMPRODUCT(ISNUMBER(TC!$A$4:$A$123)*(TC!$C$4:$C$123=$A10)*(TC!$J$4:$J$123="")*(TC!$I$4:$I$123="Fail")) | D10: =SUMPRODUCT(ISNUMBER(TC!$A$4:$A$123)*(TC!$C$4:$C$123=$A10)*(TC!$J$4:$J$123="Block"))+SUMPRODUCT(ISNUMBER(TC!$A$4:$A$123)*(TC!$C$4:$C$123=$A10)*(TC!$J$4:$J$123="")*(TC!$I$4:$I$123="Block")) | E10: =SUMPRODUCT(ISNUMBER(TC!$A$4:$A$123)*(TC!$C$4:$C$123=$A10)*(TC!$J$4:$J$123="N/A"))+SUMPRODUCT(ISNUMBER(TC!$A$4:$A$123)*(TC!$C$4:$C$123=$A10)*(TC!$J$4:$J$123="")*(TC!$I$4:$I$123="N/A")) | F10: =SUMPRODUCT(ISNUMBER(TC!$A$4:$A$123)*(TC!$C$4:$C$123=$A10)*(TC!$J$4:$J$123="N/T"))+SUMPRODUCT(ISNUMBER(TC!$A$4:$A$123)*(TC!$C$4:$C$123=$A10)*(TC!$J$4:$J$123="")*(TC!$I$4:$I$123="N/T"))+SUMPRODUCT(ISNUMBER(TC!$A$4:$A$123)*(TC!$C$4:$C$123=$A10)*(TC!$J$4:$J$123="")*(TC!$I$4:$I$123="")) | G10: =SUMPRODUCT(ISNUMBER(TC!$A$4:$A$123)*(TC!$C$4:$C$123=$A10)) | H10: =IF(G10=0,0,(G10-F10)/G10) | I10: =IF(G10-E10=0,0,B10/(G10-E10))
A11: 개선 | B11: =SUMPRODUCT(ISNUMBER(TC!$A$4:$A$123)*(TC!$C$4:$C$123=$A11)*(TC!$J$4:$J$123="Pass"))+SUMPRODUCT(ISNUMBER(TC!$A$4:$A$123)*(TC!$C$4:$C$123=$A11)*(TC!$J$4:$J$123="")*(TC!$I$4:$I$123="Pass")) | C11: =SUMPRODUCT(ISNUMBER(TC!$A$4:$A$123)*(TC!$C$4:$C$123=$A11)*(TC!$J$4:$J$123="Fail"))+SUMPRODUCT(ISNUMBER(TC!$A$4:$A$123)*(TC!$C$4:$C$123=$A11)*(TC!$J$4:$J$123="")*(TC!$I$4:$I$123="Fail")) | D11: =SUMPRODUCT(ISNUMBER(TC!$A$4:$A$123)*(TC!$C$4:$C$123=$A11)*(TC!$J$4:$J$123="Block"))+SUMPRODUCT(ISNUMBER(TC!$A$4:$A$123)*(TC!$C$4:$C$123=$A11)*(TC!$J$4:$J$123="")*(TC!$I$4:$I$123="Block")) | E11: =SUMPRODUCT(ISNUMBER(TC!$A$4:$A$123)*(TC!$C$4:$C$123=$A11)*(TC!$J$4:$J$123="N/A"))+SUMPRODUCT(ISNUMBER(TC!$A$4:$A$123)*(TC!$C$4:$C$123=$A11)*(TC!$J$4:$J$123="")*(TC!$I$4:$I$123="N/A")) | F11: =SUMPRODUCT(ISNUMBER(TC!$A$4:$A$123)*(TC!$C$4:$C$123=$A11)*(TC!$J$4:$J$123="N/T"))+SUMPRODUCT(ISNUMBER(TC!$A$4:$A$123)*(TC!$C$4:$C$123=$A11)*(TC!$J$4:$J$123="")*(TC!$I$4:$I$123="N/T"))+SUMPRODUCT(ISNUMBER(TC!$A$4:$A$123)*(TC!$C$4:$C$123=$A11)*(TC!$J$4:$J$123="")*(TC!$I$4:$I$123="")) | G11: =SUMPRODUCT(ISNUMBER(TC!$A$4:$A$123)*(TC!$C$4:$C$123=$A11)) | H11: =IF(G11=0,0,(G11-F11)/G11) | I11: =IF(G11-E11=0,0,B11/(G11-E11))
A12: 이벤트·상점 | B12: =SUMPRODUCT(ISNUMBER(TC!$A$4:$A$123)*(TC!$C$4:$C$123=$A12)*(TC!$J$4:$J$123="Pass"))+SUMPRODUCT(ISNUMBER(TC!$A$4:$A$123)*(TC!$C$4:$C$123=$A12)*(TC!$J$4:$J$123="")*(TC!$I$4:$I$123="Pass")) | C12: =SUMPRODUCT(ISNUMBER(TC!$A$4:$A$123)*(TC!$C$4:$C$123=$A12)*(TC!$J$4:$J$123="Fail"))+SUMPRODUCT(ISNUMBER(TC!$A$4:$A$123)*(TC!$C$4:$C$123=$A12)*(TC!$J$4:$J$123="")*(TC!$I$4:$I$123="Fail")) | D12: =SUMPRODUCT(ISNUMBER(TC!$A$4:$A$123)*(TC!$C$4:$C$123=$A12)*(TC!$J$4:$J$123="Block"))+SUMPRODUCT(ISNUMBER(TC!$A$4:$A$123)*(TC!$C$4:$C$123=$A12)*(TC!$J$4:$J$123="")*(TC!$I$4:$I$123="Block")) | E12: =SUMPRODUCT(ISNUMBER(TC!$A$4:$A$123)*(TC!$C$4:$C$123=$A12)*(TC!$J$4:$J$123="N/A"))+SUMPRODUCT(ISNUMBER(TC!$A$4:$A$123)*(TC!$C$4:$C$123=$A12)*(TC!$J$4:$J$123="")*(TC!$I$4:$I$123="N/A")) | F12: =SUMPRODUCT(ISNUMBER(TC!$A$4:$A$123)*(TC!$C$4:$C$123=$A12)*(TC!$J$4:$J$123="N/T"))+SUMPRODUCT(ISNUMBER(TC!$A$4:$A$123)*(TC!$C$4:$C$123=$A12)*(TC!$J$4:$J$123="")*(TC!$I$4:$I$123="N/T"))+SUMPRODUCT(ISNUMBER(TC!$A$4:$A$123)*(TC!$C$4:$C$123=$A12)*(TC!$J$4:$J$123="")*(TC!$I$4:$I$123="")) | G12: =SUMPRODUCT(ISNUMBER(TC!$A$4:$A$123)*(TC!$C$4:$C$123=$A12)) | H12: =IF(G12=0,0,(G12-F12)/G12) | I12: =IF(G12-E12=0,0,B12/(G12-E12))
A13: 밸런스 | B13: =SUMPRODUCT(ISNUMBER(TC!$A$4:$A$123)*(TC!$C$4:$C$123=$A13)*(TC!$J$4:$J$123="Pass"))+SUMPRODUCT(ISNUMBER(TC!$A$4:$A$123)*(TC!$C$4:$C$123=$A13)*(TC!$J$4:$J$123="")*(TC!$I$4:$I$123="Pass")) | C13: =SUMPRODUCT(ISNUMBER(TC!$A$4:$A$123)*(TC!$C$4:$C$123=$A13)*(TC!$J$4:$J$123="Fail"))+SUMPRODUCT(ISNUMBER(TC!$A$4:$A$123)*(TC!$C$4:$C$123=$A13)*(TC!$J$4:$J$123="")*(TC!$I$4:$I$123="Fail")) | D13: =SUMPRODUCT(ISNUMBER(TC!$A$4:$A$123)*(TC!$C$4:$C$123=$A13)*(TC!$J$4:$J$123="Block"))+SUMPRODUCT(ISNUMBER(TC!$A$4:$A$123)*(TC!$C$4:$C$123=$A13)*(TC!$J$4:$J$123="")*(TC!$I$4:$I$123="Block")) | E13: =SUMPRODUCT(ISNUMBER(TC!$A$4:$A$123)*(TC!$C$4:$C$123=$A13)*(TC!$J$4:$J$123="N/A"))+SUMPRODUCT(ISNUMBER(TC!$A$4:$A$123)*(TC!$C$4:$C$123=$A13)*(TC!$J$4:$J$123="")*(TC!$I$4:$I$123="N/A")) | F13: =SUMPRODUCT(ISNUMBER(TC!$A$4:$A$123)*(TC!$C$4:$C$123=$A13)*(TC!$J$4:$J$123="N/T"))+SUMPRODUCT(ISNUMBER(TC!$A$4:$A$123)*(TC!$C$4:$C$123=$A13)*(TC!$J$4:$J$123="")*(TC!$I$4:$I$123="N/T"))+SUMPRODUCT(ISNUMBER(TC!$A$4:$A$123)*(TC!$C$4:$C$123=$A13)*(TC!$J$4:$J$123="")*(TC!$I$4:$I$123="")) | G13: =SUMPRODUCT(ISNUMBER(TC!$A$4:$A$123)*(TC!$C$4:$C$123=$A13)) | H13: =IF(G13=0,0,(G13-F13)/G13) | I13: =IF(G13-E13=0,0,B13/(G13-E13))
A14: 합계 | B14: =SUM(B9:B13) | C14: =SUM(C9:C13) | D14: =SUM(D9:D13) | E14: =SUM(E9:E13) | F14: =SUM(F9:F13) | G14: =SUM(G9:G13) | H14: =IF(G14=0,0,(G14-F14)/G14) | I14: =IF(G14-E14=0,0,B14/(G14-E14))
A16: ※ 대분류는 TC 시트 C열 값으로 집계합니다. 2차 결과가 있으면 2차, 없으면 1차 기준이며 빈 칸은 N/T로 셉니다.
A17: 결과 값: Pass 기대 결과와 일치 / Fail 기대 결과와 다름(BTS에 Jira 키) / Block 다른 문제로 진행 불가(비고에 사유) / N/A 이 환경·계정에 해당 없음 / N/T 아직 실행 안 함
A18: 진행률 = (전체 − N/T) ÷ 전체, 성공률 = Pass ÷ (전체 − N/A)

Sheet 테스트 계획
A1: 트릭컬 리바이브 — 10/15 업데이트 검증 테스트 계획
A3: 대상 | B3: 트릭컬 리바이브 10/15(목) 정기점검 업데이트
A4: 근거 자료 | B4: 공식 공지 '10월 15일(목) 업데이트 예정 내역 안내' (네이버 게임 라운지 게시글 8324916). 예정 내역이라 실제 적용 내용은 게임 안에서 다시 대조
A5: 앱 버전 | B5: 1.6.61
A6: 기기 1 | B6: iPhone 14 / iOS 18.7.8
A7: 기기 2 | B7: MuMu 앱플레이어 / Android 버전: Android 15, 4코어, 6GB, Galaxy A52s 5G
A8: 계정 조건 | B8: 계정 생성 181일 이상(숙련 교주 그룹) / 메인 스토리 39-10 진행 / 차원 대충돌 참여 가능 / Apple 연동
A9: 테스트 기간 | B9: 2026-10-15 ~ 2026-10-22 (기간 한정 콘텐츠 종료: 10/22 10:59)
A10: 담당자 | B10: 김성재
A11: 제외 사항 | B11: 유료 결제는 하지 않음. 상점 항목은 화면 표시(가격·할인율·판매 기간)까지만 확인
A13: 우선순위 기준
A14: 상 | B14: 공지에 '수정했다'고 명시된 오류. 업데이트가 제대로 적용됐는지를 직접 보여 주는 항목
A15: 중 | B15: 10/22 10:59에 끝나는 기간 한정 콘텐츠. 기간 안에 확인하지 못하면 다시 확인할 기회가 없음
A16: 하 | B16: 기간 제한이 없어 언제든 확인할 수 있는 추가·개선 항목
A17: 위험도 | B17: 우선순위 = 발생 가능성 × 문제가 생겼을 때 플레이어가 받는 영향. 기간 제약은 영향에 포함해 판단
A19: 테스트 범위
A20: No | B20: 분류 | C20: 항목 | D20: 확인할 것 | E20: 가능 여부 | F20: 사유 | G20: 우선순위 | H20: 기한 | I20: TC 수
A21: 1 | B21: 신규 콘텐츠 | C21: 차원 대충돌 2.0 BETA [광기] 시즌 | D21: 기간, 두 차원 구조, 차원 간 사도 중복 사용 불가, 기록 초기화 | E21: 가능 | G21: 중 | H21: 10/22 10:59 | I21: =COUNTIF(TC!$B$4:$B$123,A21)
A22: 2 | B22: 신규 콘텐츠 | C22: 림의 이면세계 | D22: 아티팩트 카드 구매 횟수 제한, 스테이지 구간 선택, 코인·이면의 파편 획득 | E22: 가능 | G22: 중 | H22: 10/22 10:59 | I22: =COUNTIF(TC!$B$4:$B$123,A22)
A23: 3 | B23: 신규 콘텐츠 | C23: 셰이디의 차원 | D23: 모든 카드 구매 가능, 미보유 카드 1레벨 사용, 보스 순서 클리어, 특수 디버프 조건 충족 시 이점 | E23: 가능 | G23: 중 | H23: 10/22 10:59 | I23: =COUNTIF(TC!$B$4:$B$123,A23)
A24: 4 | B24: 신규 콘텐츠 | C24: 이면의 파편 | D24: 레벨업에 따른 버프 강화, 로비에서 초기화·재설정 | E24: 가능 | G24: 중 | H24: 10/22 10:59 | I24: =COUNTIF(TC!$B$4:$B$123,A24)
A25: 5 | B25: 신규 콘텐츠 | C25: 그룹 규칙 | D25: 숙련 교주 그룹으로 표시되는지 | E25: 일부 가능 | F25: 계정이 181일 이상이라 숙련 그룹만 확인 가능. 새싹 그룹(180일 이하)은 N/A | G25: 중 | H25: 10/22 10:59 | I25: =COUNTIF(TC!$B$4:$B$123,A25)
A26: 6 | B26: 밸런스 | C26: 냉정 사도가 받는 피해량 20% 감소 | D26: 공통 규칙 문구가 공지와 같게 표시되는지 | E26: 일부 가능 | F26: 규칙 문구 표시만 확인 가능. 실제 피해 감소 수치는 패치 전 수치를 측정할 수 없고 피해 공식이 공개되지 않아 검증 불가 | G26: 중 | H26: 10/22 10:59 | I26: =COUNTIF(TC!$B$4:$B$123,A26)
A27: 7 | B27: 신규 콘텐츠 | C27: 메인 스토리 시즌3 8챕터 1~7화 | D27: 해금 조건(28월드 2·5스테이지)을 이미 넘긴 계정에서 업데이트 직후 바로 열리는지 | E27: 가능 | F27: 진행도가 39-10이라 '클리어 전 잠김'은 확인 불가 | G27: 하 | I27: =COUNTIF(TC!$B$4:$B$123,A27)
A28: 8 | B28: 신규 콘텐츠 | C28: 테마 [사복] 미니 스토리 | D28: 추가 여부, 열람 | E28: 가능 | G28: 하 | I28: =COUNTIF(TC!$B$4:$B$123,A28)
A29: 9 | B29: 신규 콘텐츠 | C29: 기록소 > 도감 > 기억 조각 | D29: 시즌3 8챕터 1~7화 추가 여부 | E29: 가능 | G29: 하 | I29: =COUNTIF(TC!$B$4:$B$123,A29)
A30: 10 | B30: 개선 | C30: 테마극장 <마음의 들판에 두고 온 기억> | D30: 이벤트 스테이지 클리어 없이 스토리 열람 가능한지 | E30: 가능 | G30: 하 | I30: =COUNTIF(TC!$B$4:$B$123,A30)
A31: 11 | B31: 개선 | C31: 보드 만개 연출 자동 스킵 | D31: - | E31: N/A | F31: 현재 계정 진행도로는 보드 만개를 진행할 수 없음 | G31: - | I31: =COUNTIF(TC!$B$4:$B$123,A31)
A32: 12 | B32: 개선 | C32: 보드 가이드 BETA 필터·정렬 | D32: 관문별 필터, 정렬 동작 | E32: 가능 | G32: 하 | I32: =COUNTIF(TC!$B$4:$B$123,A32)
A33: 13 | B33: 개선 | C33: 게임 내 로딩 속도 | D33: - | E33: N/A | F33: 이전 버전으로 되돌려 비교할 수 없음 | G33: - | I33: =COUNTIF(TC!$B$4:$B$123,A33)
A34: 14 | B34: 이벤트·상점 | C34: [테마 사복] 5종 할인 & 특별 픽업 사도 모집 | D34: 화면 표시(할인율, 기간, 픽업 대상) | E34: 일부 가능 | F34: 결제하지 않음. 화면 표시만 확인 | G34: 중 | H34: 10/22 10:59 | I34: =COUNTIF(TC!$B$4:$B$123,A34)
A35: 15 | B35: 이벤트·상점 | C35: 캐시 상점 신규 패키지 | D35: 판매 여부, 표시 가격, 판매 기간 | E35: 일부 가능 | F35: 결제하지 않음. 화면 표시만 확인 | G35: 중 | H35: 10/22 10:59 | I35: =COUNTIF(TC!$B$4:$B$123,A35)
A36: 16 | B36: 이벤트·상점 | C36: [테마 사복] 5종 세트 40% 할인 | D36: 할인율 40% 표시, 기간, 종료 후(10/22 11:00 이후) 정가로 부띠끄 샵 입점 | E36: 일부 가능 | F36: 결제하지 않음. 화면 표시만 확인 | G36: 중 | H36: 10/22 10:59 | I36: =COUNTIF(TC!$B$4:$B$123,A36)
A37: 17 | B37: 이벤트·상점 | C37: [그치지 않는 백귀야행 로비] 패키지 | D37: 판매 여부, 표시 가격, 판매 기간 | E37: 일부 가능 | F37: 결제하지 않음. 화면 표시만 확인 | G37: 중 | H37: 10/22 10:59 | I37: =COUNTIF(TC!$B$4:$B$123,A37)
A38: 18 | B38: 오류 수정 | C38: 데이트 연출·텍스트 어색하게 출력 | D38: 수정 확인 + 주변 회귀 | E38: 가능 | F38: 공지에 대상 데이트·조건이 없어 대표 케이스로 확인 | G38: 상 | I38: =COUNTIF(TC!$B$4:$B$123,A38)
A39: 19 | B39: 오류 수정 | C39: [저편의 경계에서] 로비 애니메이션 일부 어색 | D39: 수정 확인 + 주변 회귀 | E39: N/A | F39: [저편의 경계에서] 로비를 보유하지 않은 계정이라 확인 불가 | G39: - | I39: =COUNTIF(TC!$B$4:$B$123,A39)
A40: 20 | B40: 오류 수정 | C40: 우로스 전환 설정 후 만찬장 초대 시 대사 어색 | D40: 수정 확인 + 주변 회귀 | E40: 가능 | G40: 상 | I40: =COUNTIF(TC!$B$4:$B$123,A40)
A41: 21 | B41: 오류 수정 | C41: 특정 상황에서 보드 가이드 UI 비정상 노출 | D41: 수정 확인 + 주변 회귀 | E41: 가능 | F41: 공지에 '특정 상황'이 무엇인지 없음 | G41: 상 | I41: =COUNTIF(TC!$B$4:$B$123,A41)
A42: 22 | B42: 오류 수정 | C42: 기기 OS가 다를 때 연동 로그인 간헐적 실패 | D42: iPhone(iOS) ↔ MuMu(Android) 같은 계정 로그인 | E42: 미정 | F42: Apple 연동 계정. MuMu 접속 방법이 공식 기능이면 가능, 우회 방법이면 N/A | I42: =COUNTIF(TC!$B$4:$B$123,A42)
A43: 23-1 | B43: 오류 수정 | C43: 장비 제작 네비게이션 신규 월드 첫 진입 해금 연출 | D43: - | E43: N/A | F43: 진행도상 신규 월드 첫 진입 상황을 다시 만들 수 없음 | G43: - | I43: =COUNTIF(TC!$B$4:$B$123,A43)
...

Sheet TC
A1: 트릭컬 리바이브 — 10/15 업데이트 검증 테스트 케이스
A2: 관련 항목 = '테스트 계획' 시트의 No. 기대결과는 공지 문구를 눈으로 판정할 수 있는 말로 바꿔 작성 (예: '어색함' → '끊김·겹침·깜빡임·잘림 없음'). 공지에 조건이 없으면 비고에 가정을 적습니다. 1번 행은 작성 예시이며 그대로 실행해도 됩니다.
A3: No | B3: 관련 항목 | C3: 대분류 | D3: 중분류 | E3: 소분류 | F3: 사전조건 | G3: 테스트 스텝 | H3: 기대결과 | I3: 1차 결과 | J3: 2차 결과 | K3: BTS | L3: 비고
A4: 1 | B4: 19 | C4: 오류 수정 | D4: 로비 | E4: [저편의 경계에서] 애니메이션 | F4: 1. [저편의 경계에서] 로비를 보유하고 로비로 설정한 상태 | G4: 1. 로비 화면에 진입한다 2. 애니메이션이 한 바퀴 이상 반복될 때까지 지켜본다 | H4: 애니메이션이 끊김, 겹침, 깜빡임, 잘림 없이 반복 재생됨 | I4: N/A | L4: [저편의 경계에서] 로비를 보유하지 않은 계정이라 확인 불가 (구매하지 않음)
A5: 2 | B5: 18 | C5: 오류 수정 | D5: 데이트 | E5: 텍스트 | F5: 1. 데이트를 진행할 사도를 보유한 상태 (사도: 에르핀(왕도)) | G5: 1. 빵주 화면에 진입한다. 2. 라운지 버튼을 눌러 라운지 화면에 진입한다. 3. 연락하기 버튼으로 사도를 선택해 데이트를 시작한다. 4. 데이트를 마지막 대사까지 스킵 없이 진행한다. | H5: 모든 대사에서 아래 현상이 없음 1. 글자 깨짐 2. 말풍선 밖으로 넘침 3. 문장 잘림 4. 코드 문자({이름} 등) 노출 5. 사도 이름과 대사 불일치 | I5: Pass | L5: 공지에 수정 전 현상이 없어 정상 출력 기준으로 확인 대표 케이스 사도: 에르핀(왕도)
A6: 3 | B6: 18 | C6: 오류 수정 | D6: 데이트 | E6: 연출 | F6: 1. 데이트를 진행할 사도를 보유한 상태 (사도: 에르핀(왕도)) | G6: 1. 빵주 화면에 진입한다. 2. 라운지 버튼을 눌러 라운지 화면에 진입한다. 3. 연락하기 버튼으로 사도를 선택해 데이트를 시작한다. 4. 데이트를 마지막 대사까지 스킵 없이 진행한다. | H6: 모든 연출에서 아래 현상이 없음 1. 대사가 표시될 때 해당 연출이 시작되고, 다음 대사로 넘어간 뒤에 시작되거나 남아 있지 않음 2. 연출이 화면 밖으로 잘리지 않음 3. 연출 중 사도나 배경이 깜빡이거나, 사라지거나, 겹치지 않음 | I6: Pass | L6: 공지에 수정 전 현상이 없어 정상 출력 기준으로 확인 대표 케이스 사도: 에르핀(왕도)
A7: 4 | B7: 20 | C7: 오류 수정 | D7: 만찬장 | E7: 텍스트 (전환 상태) | F7: 1. 우로스를 보유한 상태 | G7: 1. 메인 화면에서 사도를 클릭한다. 2. 사도에서 우로스를 클릭한다. 3. 하단에 이름표를 봐서 이름이 우로스(사악)인지 확인한다.(우로스이면 전환 버튼을 클릭해 사악으로 바꾼다) 4. 만찬장으로 이동하고 우로스를 초대한다. 5. 초대 후 대사를 스킵 없이 확인한다. | H7: 초대 후 모든 대사에서 1. 아래 현상이 없음 - 글자 깨짐 - 말풍선 밖으로 넘침 - 문장 잘림 - 코드 문자({이름} 등) 노출 - 사도 이름과 대사 불일치 2. 전환한 형태(사악)에 맞는 이름과 대사가 출력됨 | I7: Pass | L7: 공지에 수정 전 현상이 없어 정상 출력 기준으로 확인
A8: 5 | B8: 20 | C8: 오류 수정 | D8: 만찬장 | E8: 텍스트 (기본 상태, 회귀) | F8: 1. 우로스를 보유한 상태 | G8: 1. 메인 화면에서 사도를 클릭한다. 2. 사도에서 우로스를 클릭한다. 3. 하단에 이름표를 봐서 이름이 우로스인지 확인한다.(우로스(사악)이면 전환 버튼을 클릭해 기본 형태로 바꾼다) 4. 만찬장으로 이동하고 우로스를 초대한다. 5. 초대 후 대사를 스킵 없이 확인한다. | H8: 초대 후 모든 대사에서 1. 아래 현상이 없음 - 글자 깨짐 - 말풍선 밖으로 넘침 - 문장 잘림 - 코드 문자({이름} 등) 노출 - 사도 이름과 대사 불일치 2. 기본 형태에 맞는 이름과 대사가 출력됨 | I8: Pass | L8: No 4의 회귀 확인
A9: 6 | B9: 23-2 | C9: 오류 수정 | D9: 우편 | F9: 10/15 정기점검 이후 접속한 계정 | G9: 1. 우편함을 연다 2. 해금 보상 관련 우편이 있는지 확인한다. | H9: 대상 계정이면 누락 해금 보상 우편이 도착해 있음 | I9: N/A | L9: 우편함과 수령 기록 모두 해금 보상 우편 없음. 공지에 지급 대상 범위가 없어 본 계정이 대상인지 판정할 수 없음. 10/22 재확인 예정
A10: 7 | B10: 21 | C10: 오류 수정 | D10: 보드 가이드 | E10: UI 노출 | F10: 1. 한 명 이상의 사도를 보유한 상태 (사도: 에르핀(왕도)) | G10: 1. 메인 화면에서 사도를 클릭한다. 2. 사도를 클릭한다. 3. 좌측 보드 버튼을 클릭한다. 4. 우측 하단 보드 가이드를 클릭한다. 5. 보드 가이드 안에서 스크롤 등 조작을 한다. 6. 보드 가이드를 닫는다. | H10: 보드 가이드 UI에서 아래 현상이 없음 1. UI끼리 겹침 2. UI가 화면 밖으로 나감 3. 글자 잘림 4. 조작 중 UI가 깜빡이거나 사라짐 5. 닫은 뒤 가이드 UI가 화면에 남아 있음 | I10: Pass | L10: 공지에 발생 상황이 명시되지 않아 일반 사용 흐름(열기 → 조작 → 닫기)으로 확인
A11: 8 | B11: 1 | C11: 신규 콘텐츠 | D11: 차원 대충돌 2.0 BETA [광기] 시즌 | E11: 기간 | F11: 1. 10/15 정기점검 이후 접속한 상태 2. 차원 대충돌에 참여할 수 있는 진행도(침략 순한맛 5-10 클리어) | G11: 1. 메인 화면에서 우측 하단의 모험 버튼을 클릭한다. 2. 좌측 하단에 있는 차원 대충돌 2.0 아래 남은 시간을 확인한다. 3. 차원 대충돌 2.0을 클릭한다. 4. 차원 대충돌 2.0 내부에서도 남은 시간을 확인한다. | H11: 1. 모험 화면의 차원 대충돌 2.0 남은 시간이 공지의 종료 시각(10/22 10:59)과 일치함 2. 차원 대충돌 2.0 화면 안의 남은 시간도 공지의 종료 시각과 일치함 3. 두 화면의 남은 시간 표기가 서로 같음 | I11: Pass | L11: 1차 테스트 시간 10/16 19:11 남은 시간 05일 15시간 47분
A12: 9 | B12: 1 | C12: 신규 콘텐츠 | D12: 차원 대충돌 2.0 BETA [광기] 시즌 | E12: 두 차원 구조 | F12: 1. 두 명 이상의 사도를 보유한 상태 | G12: 1. 모험 -> 차원 대충돌 2.0에 입장한다. 2. 림의 이면세계와 셰이디의 차원이 동시에 열려있는 지 확인한다. 3. 두 세계를 번갈아 가면서 입장이 되는 지 확인한다. | H12: 1. 차원 대충돌 2.0에 입장 시 림의 이면세계와 셰이디의 차원 버튼이 활성화 되어있음 2. 림의 이면세계 버튼 클릭시 림의 이면세계 로 입장 3. 셰이디의 차원 버튼 클릭 시 셰이디의 차원 입장 | I12: Pass
A13: 10 | B13: 1 | C13: 신규 콘텐츠 | D13: 차원 대충돌 2.0 BETA [광기] 시즌 | E13: 차원 간 사도 중복 사용 불가 (빈자리 있음) | F13: 1. 두 명 이상의 사도를 보유한 상태 (사도 A: 시온 더 다크불릿) 2. 셰이디의 차원 편성에서 사도 A의 배치 줄에 빈자리가 있는 상태 | G13: 1. 모험 → 차원 대충돌 2.0에 입장한다. 2. 림의 이면세계에서 사도 A를 편성해 전투를 1회 진행한다. 3. 셰이디의 차원으로 이동해 편성 화면을 연다. 4. 사도 A를 클릭한다. | H13: 1. 사도 A가 사용 중 UI로 잠겨 있음 2. 사도 A 클릭 시 「림의 이면세계에 속해 있는 사도는 편성할 수 없습니다」 문구가 표시되고 편성되지 않음 | I13: Pass | L13: 확인: 2026-10-16 17:55 / iPhone 14
A14: 11 | B14: 1 | C14: 신규 콘텐츠 | D14: 차원 대충돌 2.0 BETA [광기] 시즌 | E14: 차원 간 사도 중복 사용 불가 (빈자리 없음) | F14: 1. No 10과 같은 상태 (사도 A: 시온 더 다크불릿) 2. 셰이디의 차원 편성에서 사도 A의 배치 줄에 빈자리가 없는 상태 | G14: 1. 모험 → 차원 대충돌 2.0에 입장한다. 2. 셰이디의 차원 편성 화면을 연다. 3. 사도 A를 클릭한다. | H14: 1. 사도 A가 사용 중 UI로 잠겨 있음 2. 사도 A가 편성되지 않음 | I14: Pass | K14: ISSUE-001 / TRK-1 | L14: 편성은 막히지만 안내 문구가 사용 중 사유가 아닌 「○열에는 더 이상 빈 자리가 없어요…」로 표시됨. 줄에 빈자리가 있을 때만 사용 중 문구가 표시됨(No 10과 비교) → 개선 제안 확인: 2026-10-16 17:55 / iPhone 14
A15: 12 | B15: 1 | C15: 신규 콘텐츠 | D15: 차원 대충돌 2.0 BETA [광기] 시즌 | E15: 기록 초기화 | F15: 1. No 10을 마친 상태 (사도 A가 림의 이면세계 사용으로 잠김) | G15: 1. 차원 대충돌 2.0 화면에서 기록 초기화 버튼을 누른다. [확인 필요: 버튼 위치] 2. 초기화 안내 문구를 확인하고 진행한다. 3. 셰이디의 차원 편성 화면을 연다. 4. 사도 A를 편성한다. | H15: 1. 초기화 전 안내 문구에 초기화되는 범위가 표시됨 2. 초기화 후 사도 A의 사용 중 표시가 사라짐 3. 사도 A를 셰이디의 차원에 편성할 수 있음 4. 안내 문구에 적힌 범위 밖의 항목(이미 받은 보상 등)은 그대로 유지됨 | I15: Pass | L15: 초기화 범위(한쪽 차원/두 차원)는 공지에 없어 게임 내 안내 문구 기준으로 판정. 실행 전 안내 문구 캡처. 실제 진행 기록이 지워지므로 시즌 진행에 손해가 없을 때 실행
A16: 13 | B16: 2 | C16: 신규 콘텐츠 | D16: 림의 이면세계 | E16: 아티팩트 카드 구매 횟수 | F16: 1. 림의 이면세계에 입장할 수 있는 상태 2. 카드 구매에 필요한 재화를 남은 구매 횟수 이상 보유한 상태 | G16: 1. 림의 이면세계에 입장한다. 2. 아티팩트 카드 구매 화면에서 남은 구매 횟수를 확인한다. 3. 카드를 1장 구매하고 남은 횟수를 다시 확인한다. 4. 남은 횟수를 모두 쓸 때까지 구매한다. 5. 횟수를 모두 쓴 뒤 한 번 더 구매를 시도한다. | H16: 1. 카드를 구매할 때마다 남은 구매 횟수가 1씩 줄어듦 2. 횟수를 모두 쓰면 추가 구매가 되지 않음 3. 구매되지 않은 시도에서는 재화가 차감되지 않음 | I16: Pass | L16: 구매 재화 종류와 횟수 기준(스테이지별/시즌 전체)은 실행 시 확인해 기록 1차 테스트 : 9회/ 제 3구간 61단계
A17: 14 | B17: 2 | C17: 신규 콘텐츠 | D17: 림의 이면세계 | E17: 스테이지 구간 선택 | F17: 1. 림의 이면세계에 입장할 수 있는 상태 | G17: 1. 림의 이면세계에 입장한다. 2. 스테이지 구간 선택 화면을 확인한다. 3. 구간 하나를 선택해 전투를 시작한다. | H17: 1. 스테이지 구간을 선택할 수 있는 UI가 표시됨 2. 선택한 구간의 전투로 진입함 3. 전투에서 다수의 몬스터가 등장함 | I17: Pass | L17: 선택한 구간: 제 3구간 61단계
A18: 15 | B18: 2 | C18: 신규 콘텐츠 | D18: 림의 이면세계 | E18: 클리어 보상 | F18: 1. 림의 이면세계에 입장할 수 있는 상태 2. 전투 전 코인과 이면의 파편 보유량을 기록한 상태 | G18: 1. 림의 이면세계 스테이지를 클리어한다. 2. 결과 화면의 획득량을 확인한다. 3. 코인과 이면의 파편 보유량을 다시 확인한다. | H18: 1. 결과 화면에 코인 획득이 표시됨 2. 클리어 후 코인 보유량 증가분이 결과 화면의 획득량과 일치함 3. 이면의 파편은 지급 단계를 클리어했을 때만 획득됨 | I18: Pass | L18: 전투 전 보유량: 코인 100 / 파편 0 전투 후 보유량: 코인 105 / 파편 0 이면의 파편은 특정 단계 클리어 시에만 지급됨. 이번 클리어 단계(제3구간 61단계)는 지급 단계가 아니라 파편 0. 지급 단계 클리어 후 파편 획득은 No 22(레벨업 전 파편 5 보유)에서 확인 공지는 "클리어 시 코인과 이면의 파편 획득"으로만 안내되어 있음
A19: 16 | B19: 3 | C19: 신규 콘텐츠 | D19: 셰이디의 차원 | E19: 모든 카드 구매 가능 | F19: 1. 셰이디의 차원에 입장할 수 있는 상태 2. 카드 구매에 필요한 코인을 보유한 상태 3. 보유하지 않은 아티팩트 카드가 있는 상태 | G19: 1. 셰이디의 차원에 입장한다. 2. 아티팩트 카드 구매 목록을 확인한다. 3. 보유하지 않은 아티팩트 카드 1장을 구매한다. (구매 즉시 사도의 장비 칸에 장착됨) | H19: 1. 보유한 카드와 보유하지 않은 카드가 모두 구매 목록에 표시됨 2. 보유하지 않은 카드도 구매할 수 있음 3. 구매 시 코인이 차감됨 | I19: Pass | L19: 구매한 카드: 장난감 만원경
A20: 17 | B20: 3 | C20: 신규 콘텐츠 | D20: 셰이디의 차원 | E20: 미보유 아티팩트 1레벨 | F20: 1. 셰이디의 차원에 입장할 수 있는 상태 2. 평소 보유하지 않은 아티팩트 A와, 보유하고 강화한 아티팩트 B가 있는 상태(아티팩트 A:레비의 단도, 아티팩트 B: 로네의 건틀릿) 3. 아티팩트 수집 화면에서 A의 1레벨 효과 수치와 B의 현재 효과 수치를 기록한 상태 | G20: 1. 셰이디의 차원에서 아티팩트 A를 구매해 장착한다. 2. 장착된 A의 효과 설명 수치를 확인한다. 3. 아티팩트 B를 구매해 장착한다. 4. 장착된 B의 효과 설명 수치를 확인한다. | H20: 1. 보유하지 않은 A도 구매해 장착할 수 있음 2. 장착된 A의 레벨이 1로 표시됨 3. 장착된 B의 레벨이 수집 화면의 보유 레벨과 같게 표시됨 | I20: Pass | L20: A: / 표시 레벨: 1 B: / 보유 레벨: 2 / 표시 레벨: 2
A21: 18 | B21: 3 | C21: 신규 콘텐츠 | D21: 셰이디의 차원 | E21: 같은 카드 중복 구매 불가 | F21: 1. No 16을 마친 상태 | G21: 1. 아티팩트 카드 구매 목록을 다시 연다. 2. No 16에서 구매한 카드의 상태를 확인한다. 3. 그 카드를 다시 구매하려고 시도한다. | H21: 1. 이미 구매한 카드는 구매 불가 상태로 표시됨 2. 다시 구매되지 않고 코인이 차감되지 않음 | I21: Pass | L21: 공지에 없는 동작으로, 실제 게임 동작 기준으로 작성. 구매 즉시 장착되며 취소·해제 불가
A22: 19 | B22: 3 | C22: 신규 콘텐츠 | D22: 셰이디의 차원 | E22: 장비 칸 가득 참 | F22: 1. 장비 칸 3개가 모두 찬 사도가 있는 상태 (사도: 에르핀(왕도)) | G22: 1. 아티팩트 카드 구매 목록을 연다. 2. 장비 칸이 가득 찬 사도에게 장착되도록 아티팩트를 구매하려고 시도한다. | H22: 1. 구매되지 않음 2. 코인이 차감되지 않음 | I22: Pass | L22: 사도당 장비 칸 3개
A23: 20 | B23: 3 | C23: 신규 콘텐츠 | D23: 셰이디의 차원 | E23: 스테이지 순서 클리어 | F23: 1. 셰이디의 차원에서 아직 클리어하지 않은 스테이지가 2개 이상 있는 상태 | G23: 1. 셰이디의 차원 스테이지 목록을 확인한다. 2. 클리어하지 않은 스테이지 중 두 번째 스테이지를 먼저 선택한다. 3. 첫 번째 미클리어 스테이지를 클리어한다. 4. 두 번째 스테이지를 다시 선택한다. | H23: 1. 앞 스테이지를 클리어하기 전에는 다음 스테이지에 진입할 수 없음 2. 앞 스테이지 클리어 후 다음 스테이지에 진입할 수 있음 3. 스테이지에 보스가 등장함 | I23: Pass
A24: 21 | B24: 3 | C24: 신규 콘텐츠 | D24: 셰이디의 차원 | E24: 보스 특수 디버프 조건 (기절 2회) | F24: 1. 셰이디의 차원 보스 스테이지에 진입할 수 있는 상태 2. 기절을 부여할 수 있는 사도를 편성한 상태 (사도: ) | G24: 1. 보스 스테이지에 진입한다. 2. 보스에게 기절을 2회 부여한다. 3. 보스의 전멸 패턴이 발동하는 시점까지 전투를 진행한다. 4. 전멸 패턴이 파훼되는지 확인한다. | H24: 1. 기절 2회 부여 후 보스의 전멸 패턴이 파훼됨 | I24: Pass | K24: ISSUE-002 / TRK-2 | L24: 조건 출처: 외부 검색(여러 커뮤니티에 같은 내용으로 안내됨. 게임 내 안내 미확인) 파훼 시 실제로 보인 현상: 그로기 상태
A25: 22 | B25: 4 | C25: 신규 콘텐츠 | D25: 이면의 파편 | E25: 레벨업 | F25: 1. 레벨업에 필요한 이면의 파편을 보유한 상태 | G25: 1. 차원대충돌 2.0 화면 진입한다. 2. 우측 하단 이면의 파편 설정을 클릭한다. 3. 현재 레벨, 버프 설명, 파편 보유량을 확인한다. 4. 레벨업을 5회 진행한다. 5. 레벨, 버프 설명, 파편 보유량을 다시 확인한다. | H25: 1. 레벨이 5 오름 2. 레벨업에 필요한 만큼 파편이 차감됨 3. 버프 설명의 효과가 이전보다 강해짐 | I25: Pass | L25: 되XX 수 X어 레벨업 전: 0 / 공속 25%, 받는 피해량 15% / 5 레벨업 후: 5 / 공속 125%, 받는 피해량 35% / 0
A26: 23 | B26: 4 | C26: 신규 콘텐츠 | D26: 이면의 파편 | E26: 초기화·재설정 | F26: 1. 이면의 파편 레벨을 1회 이상 올린 상태 | G26: 1. 차원대충돌 2.0 화면 진입한다. 2. 우측 하단 이면의 파편 설정을 클릭한다. 3. 초기화 안내 문구를 확인하고 진행한다. 4. 레벨과 파편 보유량을 확인한다. 5. 다시 레벨을 설정한다. | H26: 1. 로비에서 초기화와 재설정이 가능함 2. 초기화 후 레벨과 파편이 안내 문구에 적힌 대로 처리됨 3. 초기화 후 다시 레벨을 설정할 수 있음 | I26: Pass | L26: 초기화 시 파편 반환 여부는 공지에 없어 안내 문구 기준으로 판정. 안내 문구 캡처
A27: 24 | B27: 5 | C27: 신규 콘텐츠 | D27: 차원 대충돌 2.0 BETA [광기] 시즌 | E27: 그룹 표시 | F27: 1. 계정 생성 181일 이상인 계정 | G27: 1. 모험 → 차원 대충돌 2.0에 입장한다. 2. 셰이디의 차원으로 입장한다. 3. 우측 상단의 그룹 표시를 확인한다. | H27: 숙련 교주 그룹으로 표시됨 | I27: Pass | L27: 새싹 교주 그룹(180일 이하)은 확인할 계정이 없어 N/A
A28: 25 | B28: 7 | C28: 신규 콘텐츠 | D28: 메인 스토리 | E28: 시즌3 8챕터 해금 | F28: 1. 침략 - 순한맛 28월드 5스테이지 이상 클리어한 상태 (본 계정: 39-10) | G28: 1. 극장 클릭하여 진입한다. 2. 좌측 하단 메인 스토리를 클릭한다. 3. 시즌3 8챕터를 선택한다. 4. 1~7화의 잠금 여부를 확인한다. | H28: 1. 시즌3 8챕터 1~7화가 모두 열려 있음 2. 각 화를 선택하면 스토리가 재생됨 | I28: Pass | L28: 해금 조건을 이미 넘긴 계정이라 클리어 전 잠김은 확인 불가
A29: 26 | B29: 8 | C29: 신규 콘텐츠 | D29: 테마 스토리 | E29: [사복] 미니 스토리 | F29: 1. 10/15 정기점검 이후 접속한 상태 | G29: 1. 이벤트 팝업을 클릭한다. 2. 촛불 하나 ! 비명 속 괴담 파티를 클릭한다. 3. 미니 스토리를 선택해 재생한다. | H29: 1. 테마 [사복] 미니 스토리가 목록에 추가되어 있음 2. 선택하면 스토리가 재생됨 | I29: Pass
A30: 27 | B30: 9 | C30: 신규 콘텐츠 | D30: 기록소 | E30: 기억 조각 | F30: 1. No 25를 확인한 상태 | G30: 1. 교단 → 기록소 → 도감 → 기억 조각으로 이동한다. 2. 시즌3 8챕터 항목을 확인한다. | H30: 시즌3 8챕터 1~7화 항목이 추가되어 있음 | I30: Pass
A31: 28 | B31: 10 | C31: 개선 | D31: 테마극장 | E31: 열람 조건 제거 | F31: 1. <마음의 들판에 두고 온 기억> 이벤트 스테이지를 클리어하지 않은 상태 | G31: 1. 이벤트를 눌러 목록으로 진입한다. 2. <마음의 들판에 두고 온 기억>을 선택한다. 3. 좌측 하단 스토리 열람을 시도한다. | H31: 이벤트 스테이지를 클리어하지 않아도 스토리를 열람할 수 있음 | I31: Pass | L31: 이미 이벤트 스테이지를 클리어한 계정이면 조건 제거는 검증 불가, 열람 가능 여부만 확인
A32: 29 | B32: 12 | C32: 개선 | D32: 보드 가이드 | E32: 관문별 필터 | F32: 1. 한 명 이상의 사도를 보유한 상태 (사도: 에르핀(왕도)) | G32: 1. 메인 화면에서 사도를 클릭한다. 2. 사도를 클릭한다. 3. 좌측 보드 버튼을 클릭한다. 4. 우측 하단 보드 가이드를 클릭한다. 5. 관문 필터에서 관문 하나를 선택한다. 6. 다른 관문으로 바꿔 선택한다. | H32: 1. 선택한 관문에 해당하는 항목만 표시됨 2. 관문을 바꾸면 목록이 바뀐 관문 기준으로 갱신됨 | I32: Pass
A33: 30 | B33: 12 | C33: 개선 | D33: 보드 가이드 | E33: 정렬 | F33: 1. No 29와 같은 상태 | G33: 1. 보드 가이드를 연다. 2. 정렬 기준을 바꾼다. 3. 목록 순서를 확인한다. | H33: 1. 정렬 기준을 바꾸면 목록 순서가 그 기준대로 바뀜 2. 정렬 후에도 필터 조건이 유지됨 | I33: Pass | L33: 사용한 정렬 기준: 추천 -> 가나다순
A34: 31 | B34: 16 | C34: 이벤트·상점 | D34: 부띠끄 샵 | E34: [테마 사복] 5종 세트 할인 | F34: 1. 10/15 정기점검 이후, 10/22 10:59 이전 | G34: 1. 캐시 상점에서 부띠끄 샵을 클릭한다. 2. 촛불 하나! 비명 속 괴담 파티! 세트 할인율, 가격, 판매 기간을 확인한다. | H34: 1. 할인율이 40%로 표시됨 2. 판매 종료가 10/22 10:59로 표시됨 3. 정가가 함께 표시되면 할인가가 정가의 60%임 | I34: Pass | L34: 결제하지 않음. 60%는 40% 할인에서 나온 값
A35: 32 | B35: 16 | C35: 이벤트·상점 | D35: 부띠끄 샵 | E35: 할인 종료 후 정가 입점 | F35: 1. 10/22 11:00 이후 | G35: 1. 부띠끄 샵에서 [테마 사복] 5종을 찾는다. 2. 가격과 판매 상태를 확인한다. | H35: 1. 할인 표시가 사라짐 2. 정가로 부띠끄 샵에 판매 중임 | I35: N/T | L35: 10/22 11:00 이후에만 실행 가능. 결제하지 않음
A36: 33 | B36: 14 | C36: 이벤트·상점 | D36: 모집 | E36: 특별 픽업 사도 모집 | F36: 1. 10/15 정기점검 이후 접속한 상태 | G36: 1. 모집 화면을 연다. 2. 특별 모집 -> 픽업 사도 선택 모집을 클릭한다. 3. 모집 기간을 확인한다. | H36: 픽업 대상 사도와 모집 기간이 공지(별도 공지 링크)와 일치함 | I36: Pass | L36: 별도 공지의 픽업 대상과 기간을 비고에 적고 비교. 결제·모집하지 않음
A37: 34 | B37: 15 | C37: 이벤트·상점 | D37: 캐시 상점 | E37: 신규 패키지 | F37: 1. 10/15 정기점검 이후, 10/22 10:59 이전 | G37: 1. 캐시 상점 → 특별 상품으로 이동한다. 2. 신규 패키지의 판매 여부와 판매 기간을 확인한다. | H37: 1. 신규 패키지가 특별 상품에 표시됨 2. 판매 종료가 10/22 10:59로 표시됨 | I37: Pass | L37: 결제하지 않음
A38: 35 | B38: 17 | C38: 이벤트·상점 | D38: 캐시 상점 | E38: [그치지 않는 백귀야행 로비] 패키지 | F38: 1. 10/15 정기점검 이후, 10/22 10:59 이전 | G38: 1. 캐시 상점 → 특별 상품으로 이동한다. 2. 특별 상품에서 [그치지 않는 백귀야행 로비] 패키지를 찾는다. 3. 구성품과 판매 기간을 확인한다. | H38: 1. 패키지 구성에 움직이는 로비가 포함되어 있음 2. 판매 종료가 10/22 10:59로 표시됨 | I38: Pass | L38: 결제하지 않음
A39: 36 | B39: 6 | C39: 밸런스 | D39: 차원 대충돌 2.0 BETA [광기] 시즌 | E39: 공통 규칙 표시 (냉정 피해 감소) | F39: 1. 차원 대충돌 2.0에 입장할 수 있는 상태 | G39: 1. 모험 → 차원 대충돌 2.0에 입장한다. 2. 셰이디의 차원에 입장한다. 3. 좌측에 있는 공통 규칙을 확인한다. | H39: 공통 규칙에 「냉정 사도가 받는 피해량 20% 감소」가 공지와 같은 내용으로 표시됨 | I39: Pass | L39: 규칙 표시만 확인. 실제 피해 감소 수치는 패치 전 수치 측정 불가, 피해 공식 비공개로 검증 불가
A40: 37 | B40: 3 | C40: 신규 콘텐츠 | D40: 셰이디의 차원 | E40: 보스 특수 디버프 조건 (기절 1회, 경계) | F40: 1. No 21과 같은 상태 | G40: 1. 보스 스테이지에 진입한다. 2. 보스에게 기절을 1회만 부여한다. 3. 보스의 전멸 패턴이 발동하는 시점까지 전투를 진행한다. | H40: 1. 기절 1회만 부여한 경우 전멸 패턴이 파훼되지 않고 그대로 발동함 | I40: Pass | L40: No 21의 경계값 확인. 조건이 정확히 2회인지 검증

Sheet 이슈
A1: 이슈 목록 (Jira 연동)
A2: Fail이 나오면 Jira에 등록하고 키를 적습니다. 상용 게임이라 직접 수정할 수 없으므로 상태는 등록 → 재현 확인 → 제보 → 다음 패치에서 수정 확인 → 종료 순서로 관리합니다.
A3: ID | B3: Jira 키 | C3: 제목 | D3: 유형 | E3: 심각도 | F3: 재현율 | G3: 관련 TC | H3: 환경 | I3: 상태 | J3: 비고
A4: ISSUE-001 | B4: TRK-1 | C4: [차원 대충돌] 셰이디의 차원에서 이면세계 사용 사도를 편성할 때, 배치 줄이 가득 차 있으면 사용 중 사유 대신 자리 부족 문구가 표시됨 | D4: 개선 제안 | E4: Trivial | F4: 항상 | G4: 11 | H4: iPhone 14 / iOS 18.7.8 / 앱 1.6.61 | I4: 제보 | J4: 편성은 정상적으로 막힘(규칙 위반 아님). 안내 문구 검사 순서 문제. 줄에 빈자리가 있으면 사용 중 문구가 정상 표시됨(TC 10) 2026-10-18 고객센터 1:1 문의(건의/제안)로 제보
A5: ISSUE-002 | B5: TRK-2 | C5: [차원 대충돌] 셰이디의 차원 보스 특수 디버프 조건(기절 2회 부여 시 전멸 패턴 파훼)의 게임 내 안내 여부 확인 요청 | D5: 확인 요청 | E5: Trivial | F5: 항상 | G5: 21 | H5: iPhone 14 / iOS 18.7.8 / 앱 1.6.61 | I5: 등록 | J5: 공지에는 조건 충족 시 이점이 있다고 명시되어 있으나, 보스 스테이지 선택·편성·전투 화면에서 조건을 확인할 수 없고 외부 검색으로만 확인됨. 플레이어가 직접 알아내는 발견형 요소로 의도된 것일 수 있어 결함으로 단정하지 않고 의도 여부 확인을 요청. 의도된 숨김이라면 힌트 수준의 안내 제공을 제안
